[2024-01-04T12:34:14.844+0000] {taskinstance.py:1159} INFO - Dependencies all met for dep_context=non-requeueable deps ti=<TaskInstance: online_retail.up_data_to_gcs manual__2024-01-04T12:14:24.430451+00:00 [queued]>
[2024-01-04T12:34:14.857+0000] {taskinstance.py:1159} INFO - Dependencies all met for dep_context=requeueable deps ti=<TaskInstance: online_retail.up_data_to_gcs manual__2024-01-04T12:14:24.430451+00:00 [queued]>
[2024-01-04T12:34:14.857+0000] {taskinstance.py:1361} INFO - Starting attempt 1 of 1
[2024-01-04T12:34:14.874+0000] {taskinstance.py:1382} INFO - Executing <Task(LocalFilesystemToGCSOperator): up_data_to_gcs> on 2024-01-04 12:14:24.430451+00:00
[2024-01-04T12:34:14.882+0000] {standard_task_runner.py:57} INFO - Started process 429 to run task
[2024-01-04T12:34:14.887+0000] {standard_task_runner.py:84} INFO - Running: ['***', 'tasks', 'run', 'online_retail', 'up_data_to_gcs', 'manual__2024-01-04T12:14:24.430451+00:00', '--job-id', '7', '--raw', '--subdir', 'DAGS_FOLDER/main.py', '--cfg-path', '/tmp/tmpkm4gaj2c']
[2024-01-04T12:34:14.889+0000] {standard_task_runner.py:85} INFO - Job 7: Subtask up_data_to_gcs
[2024-01-04T12:34:14.950+0000] {task_command.py:416} INFO - Running <TaskInstance: online_retail.up_data_to_gcs manual__2024-01-04T12:14:24.430451+00:00 [running]> on host e552979bdd1c
[2024-01-04T12:34:15.060+0000] {taskinstance.py:1662} INFO - Exporting env vars: AIRFLOW_CTX_DAG_OWNER='***' AIRFLOW_CTX_DAG_ID='online_retail' AIRFLOW_CTX_TASK_ID='up_data_to_gcs' AIRFLOW_CTX_EXECUTION_DATE='2024-01-04T12:14:24.430451+00:00' AIRFLOW_CTX_TRY_NUMBER='1' AIRFLOW_CTX_DAG_RUN_ID='manual__2024-01-04T12:14:24.430451+00:00'
[2024-01-04T12:34:15.088+0000] {taskinstance.py:1937} ERROR - Task failed with exception
Traceback (most recent call last):
  File "/home/airflow/.local/lib/python3.8/site-packages/airflow/providers/google/cloud/transfers/local_to_gcs.py", line 90, in execute
    hook = GCSHook(
  File "/home/airflow/.local/lib/python3.8/site-packages/airflow/providers/google/cloud/hooks/gcs.py", line 164, in __init__
    super().__init__(
  File "/home/airflow/.local/lib/python3.8/site-packages/airflow/providers/google/common/hooks/base_google.py", line 242, in __init__
    self.extras: dict = self.get_connection(self.gcp_conn_id).extra_dejson
  File "/home/airflow/.local/lib/python3.8/site-packages/airflow/hooks/base.py", line 72, in get_connection
    conn = Connection.get_connection_from_secrets(conn_id)
  File "/home/airflow/.local/lib/python3.8/site-packages/airflow/models/connection.py", line 477, in get_connection_from_secrets
    raise AirflowNotFoundException(f"The conn_id `{conn_id}` isn't defined")
airflow.exceptions.AirflowNotFoundException: The conn_id `google_cloud_default` isn't defined
[2024-01-04T12:34:15.097+0000] {taskinstance.py:1400} INFO - Marking task as FAILED. dag_id=online_retail, task_id=up_data_to_gcs, execution_date=20240104T121424, start_date=20240104T123414, end_date=20240104T123415
[2024-01-04T12:34:15.115+0000] {standard_task_runner.py:104} ERROR - Failed to execute job 7 for task up_data_to_gcs (The conn_id `google_cloud_default` isn't defined; 429)
[2024-01-04T12:34:15.138+0000] {local_task_job_runner.py:228} INFO - Task exited with return code 1
[2024-01-04T12:34:15.160+0000] {taskinstance.py:2778} INFO - 0 downstream tasks scheduled from follow-on schedule check
