[2024-01-04T17:05:13.424+0000] {taskinstance.py:1159} INFO - Dependencies all met for dep_context=non-requeueable deps ti=<TaskInstance: online_retail.up_data_to_gcs manual__2024-01-04T12:14:24.430451+00:00 [queued]>
[2024-01-04T17:05:13.442+0000] {taskinstance.py:1159} INFO - Dependencies all met for dep_context=requeueable deps ti=<TaskInstance: online_retail.up_data_to_gcs manual__2024-01-04T12:14:24.430451+00:00 [queued]>
[2024-01-04T17:05:13.442+0000] {taskinstance.py:1361} INFO - Starting attempt 14 of 14
[2024-01-04T17:05:13.465+0000] {taskinstance.py:1382} INFO - Executing <Task(LocalFilesystemToGCSOperator): up_data_to_gcs> on 2024-01-04 12:14:24.430451+00:00
[2024-01-04T17:05:13.477+0000] {standard_task_runner.py:57} INFO - Started process 247 to run task
[2024-01-04T17:05:13.481+0000] {standard_task_runner.py:84} INFO - Running: ['***', 'tasks', 'run', 'online_retail', 'up_data_to_gcs', 'manual__2024-01-04T12:14:24.430451+00:00', '--job-id', '40', '--raw', '--subdir', 'DAGS_FOLDER/main.py', '--cfg-path', '/tmp/tmpfoxc4kqz']
[2024-01-04T17:05:13.483+0000] {standard_task_runner.py:85} INFO - Job 40: Subtask up_data_to_gcs
[2024-01-04T17:05:13.564+0000] {task_command.py:416} INFO - Running <TaskInstance: online_retail.up_data_to_gcs manual__2024-01-04T12:14:24.430451+00:00 [running]> on host 6808d18c086e
[2024-01-04T17:05:13.698+0000] {taskinstance.py:1662} INFO - Exporting env vars: AIRFLOW_CTX_DAG_OWNER='***' AIRFLOW_CTX_DAG_ID='online_retail' AIRFLOW_CTX_TASK_ID='up_data_to_gcs' AIRFLOW_CTX_EXECUTION_DATE='2024-01-04T12:14:24.430451+00:00' AIRFLOW_CTX_TRY_NUMBER='14' AIRFLOW_CTX_DAG_RUN_ID='manual__2024-01-04T12:14:24.430451+00:00'
[2024-01-04T17:05:13.729+0000] {taskinstance.py:1937} ERROR - Task failed with exception
Traceback (most recent call last):
  File "/home/airflow/.local/lib/python3.8/site-packages/airflow/providers/google/cloud/transfers/local_to_gcs.py", line 90, in execute
    hook = GCSHook(
  File "/home/airflow/.local/lib/python3.8/site-packages/airflow/providers/google/cloud/hooks/gcs.py", line 164, in __init__
    super().__init__(
  File "/home/airflow/.local/lib/python3.8/site-packages/airflow/providers/google/common/hooks/base_google.py", line 242, in __init__
    self.extras: dict = self.get_connection(self.gcp_conn_id).extra_dejson
  File "/home/airflow/.local/lib/python3.8/site-packages/airflow/hooks/base.py", line 72, in get_connection
    conn = Connection.get_connection_from_secrets(conn_id)
  File "/home/airflow/.local/lib/python3.8/site-packages/airflow/models/connection.py", line 477, in get_connection_from_secrets
    raise AirflowNotFoundException(f"The conn_id `{conn_id}` isn't defined")
airflow.exceptions.AirflowNotFoundException: The conn_id `google_cloud_default` isn't defined
[2024-01-04T17:05:13.734+0000] {taskinstance.py:1400} INFO - Marking task as FAILED. dag_id=online_retail, task_id=up_data_to_gcs, execution_date=20240104T121424, start_date=20240104T170513, end_date=20240104T170513
[2024-01-04T17:05:13.749+0000] {standard_task_runner.py:104} ERROR - Failed to execute job 40 for task up_data_to_gcs (The conn_id `google_cloud_default` isn't defined; 247)
[2024-01-04T17:05:13.774+0000] {local_task_job_runner.py:228} INFO - Task exited with return code 1
[2024-01-04T17:05:13.813+0000] {taskinstance.py:2778} INFO - 0 downstream tasks scheduled from follow-on schedule check
