[2024-01-04T16:34:13.000+0000] {taskinstance.py:1159} INFO - Dependencies all met for dep_context=non-requeueable deps ti=<TaskInstance: online_retail.up_data_to_gcs manual__2024-01-04T12:14:24.430451+00:00 [queued]>
[2024-01-04T16:34:13.032+0000] {taskinstance.py:1159} INFO - Dependencies all met for dep_context=requeueable deps ti=<TaskInstance: online_retail.up_data_to_gcs manual__2024-01-04T12:14:24.430451+00:00 [queued]>
[2024-01-04T16:34:13.032+0000] {taskinstance.py:1361} INFO - Starting attempt 5 of 5
[2024-01-04T16:34:13.059+0000] {taskinstance.py:1382} INFO - Executing <Task(LocalFilesystemToGCSOperator): up_data_to_gcs> on 2024-01-04 12:14:24.430451+00:00
[2024-01-04T16:34:13.070+0000] {standard_task_runner.py:57} INFO - Started process 2654 to run task
[2024-01-04T16:34:13.078+0000] {standard_task_runner.py:84} INFO - Running: ['***', 'tasks', 'run', 'online_retail', 'up_data_to_gcs', 'manual__2024-01-04T12:14:24.430451+00:00', '--job-id', '27', '--raw', '--subdir', 'DAGS_FOLDER/main.py', '--cfg-path', '/tmp/tmpc1kwb_46']
[2024-01-04T16:34:13.080+0000] {standard_task_runner.py:85} INFO - Job 27: Subtask up_data_to_gcs
[2024-01-04T16:34:13.160+0000] {task_command.py:416} INFO - Running <TaskInstance: online_retail.up_data_to_gcs manual__2024-01-04T12:14:24.430451+00:00 [running]> on host e552979bdd1c
[2024-01-04T16:34:13.259+0000] {taskinstance.py:1662} INFO - Exporting env vars: AIRFLOW_CTX_DAG_OWNER='***' AIRFLOW_CTX_DAG_ID='online_retail' AIRFLOW_CTX_TASK_ID='up_data_to_gcs' AIRFLOW_CTX_EXECUTION_DATE='2024-01-04T12:14:24.430451+00:00' AIRFLOW_CTX_TRY_NUMBER='5' AIRFLOW_CTX_DAG_RUN_ID='manual__2024-01-04T12:14:24.430451+00:00'
[2024-01-04T16:34:13.308+0000] {connection.py:232} WARNING - Connection schemes (type: google_cloud_platform) shall not contain '_' according to RFC3986.
[2024-01-04T16:34:13.311+0000] {base.py:73} INFO - Using connection ID 'gcp' for task execution.
[2024-01-04T16:34:13.319+0000] {taskinstance.py:1937} ERROR - Task failed with exception
Traceback (most recent call last):
  File "/home/airflow/.local/lib/python3.8/site-packages/airflow/providers/google/cloud/transfers/local_to_gcs.py", line 110, in execute
    hook.upload(
  File "/home/airflow/.local/lib/python3.8/site-packages/airflow/providers/google/cloud/hooks/gcs.py", line 530, in upload
    client = self.get_conn()
  File "/home/airflow/.local/lib/python3.8/site-packages/airflow/providers/google/cloud/hooks/gcs.py", line 173, in get_conn
    credentials=self.get_credentials(), client_info=CLIENT_INFO, project=self.project_id
  File "/home/airflow/.local/lib/python3.8/site-packages/airflow/providers/google/common/hooks/base_google.py", line 296, in get_credentials
    credentials, _ = self.get_credentials_and_project_id()
  File "/home/airflow/.local/lib/python3.8/site-packages/airflow/providers/google/common/hooks/base_google.py", line 273, in get_credentials_and_project_id
    credentials, project_id = get_credentials_and_project_id(
  File "/home/airflow/.local/lib/python3.8/site-packages/airflow/providers/google/cloud/utils/credentials_provider.py", line 362, in get_credentials_and_project_id
    return _CredentialProvider(*args, **kwargs).get_credentials_and_project()
  File "/home/airflow/.local/lib/python3.8/site-packages/airflow/providers/google/cloud/utils/credentials_provider.py", line 235, in get_credentials_and_project
    credentials, project_id = self._get_credentials_using_key_path()
  File "/home/airflow/.local/lib/python3.8/site-packages/airflow/providers/google/cloud/utils/credentials_provider.py", line 286, in _get_credentials_using_key_path
    credentials = google.oauth2.service_account.Credentials.from_service_account_file(
  File "/home/airflow/.local/lib/python3.8/site-packages/google/oauth2/service_account.py", line 260, in from_service_account_file
    info, signer = _service_account_info.from_filename(
  File "/home/airflow/.local/lib/python3.8/site-packages/google/auth/_service_account_info.py", line 78, in from_filename
    with io.open(filename, "r", encoding="utf-8") as json_file:
FileNotFoundError: [Errno 2] No such file or directory: '/home/amangmisbah/project/dags/include/keyfile.json'
[2024-01-04T16:34:13.366+0000] {taskinstance.py:1400} INFO - Marking task as FAILED. dag_id=online_retail, task_id=up_data_to_gcs, execution_date=20240104T121424, start_date=20240104T163413, end_date=20240104T163413
[2024-01-04T16:34:13.401+0000] {standard_task_runner.py:104} ERROR - Failed to execute job 27 for task up_data_to_gcs ([Errno 2] No such file or directory: '/home/amangmisbah/project/dags/include/keyfile.json'; 2654)
[2024-01-04T16:34:13.417+0000] {local_task_job_runner.py:228} INFO - Task exited with return code 1
[2024-01-04T16:34:13.456+0000] {taskinstance.py:2778} INFO - 0 downstream tasks scheduled from follow-on schedule check
